<?xml version='1.0'?>
<robot name="panda_arm_hand">

    <link name="link0">
      <inertial>
        <origin xyz="0 0 0.05" rpy="0 0 0" />
        <mass value="4" />
        <inertia ixx="0.4" iyy="0.4" izz="0.4" ixy="0" ixz="0" iyz="0" />
      </inertial>
      <visual>
        <geometry>
          <mesh filename="link0.obj"/>
        </geometry>
      </visual>
<!--       <collision>
        <geometry>
          <mesh filename="../../../Model/meshes/link0.obj"/>
        </geometry>
      </collision> -->
    </link>
    <link name="link1">
      <inertial>
        <origin xyz="0 0 -0.07" rpy="0 -0 0" />
        <mass value="3" />
        <inertia ixx="0.3" iyy="0.3" izz="0.3" ixy="0" ixz="0" iyz="0" />
      </inertial>
      <visual>
        <geometry>
          <mesh filename="link1.obj"/>
        </geometry>
      </visual>
      <!-- <collision>
        <geometry>
          <mesh filename="../../../Model/meshes/link1.obj"/>
        </geometry>
      </collision> -->
    </link>
    <link name="link2">
      <inertial>
        <origin xyz="0 -0.1 0" rpy="0 -0 0" />
        <mass value="3" />
        <inertia ixx="0.3" iyy="0.3" izz="0.3" ixy="0" ixz="0" iyz="0" />
      </inertial>
      <visual>
        <geometry>
          <mesh filename="link2.obj"/>
        </geometry>
      </visual>
      <!-- <collision>
        <geometry>
          <mesh filename="../../../Model/meshes/link2.obj"/>
        </geometry>
      </collision> -->
    </link>
    <link name="link3">
      <inertial>
        <origin xyz="0.04 0 -0.05" rpy="0 -0 0" />
        <mass value="2" />
        <inertia ixx="0.2" iyy="0.2" izz="0.2" ixy="0" ixz="0" iyz="0" />
      </inertial>
      <visual>
        <geometry>
          <mesh filename="link3.obj"/>
        </geometry>
      </visual>
      <!-- <collision>
        <geometry>
          <mesh filename="../../../Model/meshes/link3.obj"/>
        </geometry>
      </collision> -->
    </link>
    <link name="link4">
      <inertial>
        <origin xyz="-0.04 0.05 0" rpy="0 -0 0" />
        <mass value="2" />
        <inertia ixx="0.2" iyy="0.2" izz="0.2" ixy="0" ixz="0" iyz="0" />
      </inertial>
      <visual>
        <geometry>
          <mesh filename="link4.obj"/>
        </geometry>
      </visual>
      <!-- <collision>
        <geometry>
          <mesh filename="../../../Model/meshes/link4.obj"/>
        </geometry>
      </collision> -->
    </link>
    <link name="link5">
      <inertial>
        <origin xyz="0 0 -0.15" rpy="0 -0 0" />
        <mass value="2" />
        <inertia ixx="0.2" iyy="0.2" izz="0.2" ixy="0" ixz="0" iyz="0" />
      </inertial>
      <visual>
        <geometry>
          <mesh filename="link5.obj"/>
        </geometry>
      </visual>
      <!-- <collision>
        <geometry>
          <mesh filename="../../../Model/meshes/link5.obj"/>
        </geometry>
      </collision> -->
    </link>
    <link name="link6">
      <inertial>
        <origin xyz="0.06 0 0" rpy="0 -0 0" />
        <mass value="1.5" />
        <inertia ixx="0.1" iyy="0.1" izz="0.1" ixy="0" ixz="0" iyz="0" />
      </inertial>
      <visual>
        <geometry>
          <mesh filename="link6.obj"/>
        </geometry>
      </visual>
      <!-- <collision>
        <geometry>
          <mesh filename="../../../Model/meshes/link6.obj"/>
        </geometry>
      </collision> -->
    </link>


    <link name="link7">
      <inertial>
        <origin xyz="0 0 0.17" rpy="0 -0 0" />
        <mass value="1.8" />
        <inertia ixx="0.09" iyy="0.05" izz="0.07" ixy="0" ixz="0" iyz="0" />
      </inertial>
      <visual>
        <origin xyz="0 0 0" rpy="0 0 0" />
        <geometry>
          <mesh filename="link7.obj"/>
        </geometry>
      </visual>
      <!-- <collision>
        <geometry>
          <mesh filename="../../../Model/meshes/link7.obj"/>
        </geometry>
      </collision> -->
    </link>


    
    <joint name="joint1" type="revolute">
      <safety_controller k_position="100.0" k_velocity="40.0" soft_lower_limit="-2.8973" soft_upper_limit="2.8973"/>
      <origin rpy="0 0 0" xyz="0 0 0.333"/>
      <parent link="link0"/>
      <child link="link1"/>
      <axis xyz="0 0 1"/>
      <limit effort="87" lower="-2.8973" upper="2.8973" velocity="2.1750"/>
    </joint>
    <joint name="joint2" type="revolute">
      <safety_controller k_position="100.0" k_velocity="40.0" soft_lower_limit="-1.7628" soft_upper_limit="1.7628"/>
      <origin rpy="-1.57079632679 0 0" xyz="0 0 0"/>
      <parent link="link1"/>
      <child link="link2"/>
      <axis xyz="0 0 1"/>
      <calibration falling="-45.0" />
      <limit effort="87" lower="-1.7628" upper="1.7628" velocity="2.1750"/>
    </joint>
    <joint name="joint3" type="revolute">
      <safety_controller k_position="100.0" k_velocity="40.0" soft_lower_limit="-2.8973" soft_upper_limit="2.8973"/>
      <origin rpy="1.57079632679 0 0" xyz="0 -0.316 0"/>
      <parent link="link2"/>
      <child link="link3"/>
      <axis xyz="0 0 1"/>
      <limit effort="87" lower="-2.8973" upper="2.8973" velocity="2.1750"/>
    </joint>
    <joint name="joint4" type="revolute">
      <safety_controller k_position="100.0" k_velocity="40.0" soft_lower_limit="-3.0718" soft_upper_limit="-0.0698"/>
      <origin rpy="1.57079632679 0 0" xyz="0.0825 0 0"/>
      <parent link="link3"/>
      <child link="link4"/>
      <axis xyz="0 0 1"/>
      <calibration falling="-125.0" />
      <limit effort="87" lower="-3.0718" upper="-0.0698" velocity="2.1750"/>
    </joint>
    <joint name="joint5" type="revolute">
      <safety_controller k_position="100.0" k_velocity="40.0" soft_lower_limit="-2.8973" soft_upper_limit="2.8973"/>
      <origin rpy="-1.57079632679 0 0" xyz="-0.0825 0.384 0"/>
      <parent link="link4"/>
      <child link="link5"/>
      <axis xyz="0 0 1"/>
      <limit effort="12" lower="-2.8973" upper="2.8973" velocity="2.6100"/>
    </joint>
    <joint name="joint6" type="revolute">
      <safety_controller k_position="100.0" k_velocity="40.0" soft_lower_limit="-0.0175" soft_upper_limit="3.7525"/>
      <origin rpy="1.57079632679 0 0" xyz="0 0 0"/>
      <parent link="link5"/>
      <child link="link6"/>
      <axis xyz="0 0 1"/>
      <calibration falling="80.0" />
      <limit effort="12" lower="-0.0175" upper="3.7525" velocity="2.6100"/>
    </joint>
    <joint name="joint7" type="revolute">
      <safety_controller k_position="100.0" k_velocity="40.0" soft_lower_limit="-2.8973" soft_upper_limit="2.8973"/>
      <origin rpy="1.57079632679 0 0" xyz="0.088 0 0"/>
      <parent link="link6"/>
      <child link="link7"/>
      <axis xyz="0 0 1"/>
      <limit effort="12" lower="-2.8973" upper="2.8973" velocity="2.6100"/>
    </joint>


    <link name="base_link">
        <inertial>
            <origin xyz="0.0 0.0 0.0475" rpy="0 0 0" />
            <mass value="0.4154" />
            <inertia ixx="1e-4" iyy="1e-4" izz="1e-4" ixy="0" ixz="0" iyz="0" />
        </inertial>
        <visual>
            <origin xyz="0.0 0.0 0.0" rpy="0 0 0" />
            <geometry>
                <mesh filename="base_link.obj" scale="1 1 1" />
            </geometry>
            <material name="material_red">
                <color rgba="1.0 0.1 0.1 1.0" />
            </material>
        </visual>
    </link>

    <joint name="joint_hand" type="fixed">
        <axis xyz="0 0 1"/>
        <limit effort="0" lower="-0.47" upper="0.47" velocity="0"/>
        <parent link="link7"/>
        <child link="base_link"/>
        <origin rpy="0 -1.5707963267 3.1415926535" xyz="0.13 0 0.1654"/>
    </joint>


    <link name="link_0.0">
        <inertial>
            <mass value="0.0119" />
            <origin xyz="0 0 0" rpy="0 0 0"/>
            <inertia ixx="1.01666658333e-06" ixy="0.0" ixz="0.0" iyy="6.47677333333e-07" iyz="0.0" izz=" 1.01666658333e-06" />
        </inertial>
        <visual>
            <geometry>
                <mesh filename="link_0.0.obj"/>
            </geometry>
        </visual>
        <collision>
            <!--<geometry>
                <box size="0.0196 0.0275 0.0164"/>
            </geometry>
            <origin rpy="0 0 0" xyz="0 0 0.0082"/>-->
        </collision>
    </link>  

    <joint name="joint_0.0" type="revolute">
        <axis xyz="0 0 1"/>
        <limit effort="0" lower="-0.47" upper="0.47" velocity="0"/>
        <parent link="base_link"/>
        <child link="link_0.0"/>
        <origin rpy="-0.08726646255 0 0" xyz="0 0.0435 -0.001542"/>
    </joint>

    <link name="link_1.0">
        <inertial>
            <mass value="0.065" />
            <origin xyz="0 0 0" rpy="0 0 0"/>
            <inertia ixx="7.95654166667e-05" ixy="1.7199e-05" ixz="8.75875e-06" iyy="2.47088833333e-05" iyz="2.413125e-05" izz="7.95654166667e-05" />
        </inertial>
        <visual>
            <geometry>
                <mesh filename="link_1.0.obj"/>
            </geometry>
            <material name="black"/>
        </visual>
        <collision>
            <!--<origin xyz="0 0 0" rpy="0 0 0" />
            <geometry>
                <mesh filename="link_1.0.obj" scale="1 1 1" />
            </geometry>-->
        </collision>
    </link>

    <joint name="joint_1.0" type="revolute">
        <limit effort="0" lower="-0.196" upper="1.61" velocity="0"/>
        <axis xyz="0 1 0"/>
        <parent link="link_0.0"/>
        <child link="link_1.0"/>
        <origin xyz="0 0 0.0164"/>
    </joint>
    
    <link name="link_2.0">
        <inertial>
            <mass value="0.0355" />
            <origin xyz="0 0 0" rpy="0 0 0"/>
            <inertia ixx="2.63979183333e-05" ixy="6.67968e-06" ixz="4.783625e-06"
                       iyy="1.34948516667e-05" iyz="9.372e-06"
                       izz="2.63979183333e-05" />
        </inertial>
        <visual>
            <geometry>
                <mesh filename="link_2.0.obj"/>
            </geometry>
            <material name="black"/>
        </visual>
        <collision>
            <!--<origin xyz="0 0 0" rpy="0 0 0" />
            <geometry>
                <mesh filename="link_2.0.obj" scale="1 1 1" />
            </geometry>-->
        </collision>
    </link>

    <joint name="joint_2.0" type="revolute">
        <axis xyz="0 1 0"/>
        <limit effort="0" lower="-0.174" upper="1.709" velocity="0"/>
        <parent link="link_1.0"/>
        <child link="link_2.0"/>
        <origin xyz="0 0 0.054"/>
    </joint>    

    <link name="link_3.0">
        <!--<inertial>
            <mass value="0.0096" />
            <origin xyz="0 0 0" rpy="0 0 0"/>
            <inertia ixx="4.701248e-06" ixy="1.255968e-06" ixz="1.2936e-06"
                       iyy="3.649312e-06" iyz="1.7622e-06"
                       izz="4.701248e-06" />
        </inertial>
        <inertial>
            <mass value="0.0168" />
            <origin xyz="0 0 0" rpy="0 0 0"/>
            <inertia ixx="9.68e-07" ixy="0" ixz="0"
                       iyy="9.68e-07" iyz="0"
                       izz="9.68e-07" />
        </inertial>-->
        <inertial>
            <mass value="0.1128" />
            <origin xyz="0 0 0.00397659574" rpy="0 0 0"/>
            <inertia ixx="4.701248e-06" ixy="1.255968e-06" ixz="1.2936e-06"
                       iyy="3.649312e-06" iyz="1.7622e-06"
                       izz="4.701248e-06" /> <!-- TODO: change the inertia, are you sure you can apply the parallel theorem? the inertia tensor is probably not associated to the center of mass. -->
        </inertial>
        <visual>
            <geometry>
                <mesh filename="link_3.0.obj"/>
            </geometry>
            <material name="black"/>
        </visual>
        <visual>
            <origin xyz="0.0 0.0 0.0267" rpy="0 0 0" />
            <geometry>
                <mesh filename="link_3.0_tip.obj"/>
            </geometry>
            <material name="black"/>
        </visual>
         <!--<collision>
           <origin xyz="0 0 0" rpy="0 0 0" />
            <geometry>
                <mesh filename="link_3.0.obj" scale="1 1 1" />
            </geometry>           
        </collision> --> 
        <collision>
            <origin xyz="0 0 0.0267" rpy="0 0 0" />
            <geometry>
                <!--<mesh filename="link_3.0_tip.obj" scale="1 1 1" />-->
                <sphere radius="0.012" />
            </geometry>            
        </collision>
    </link>

    <joint name="joint_3.0" type="revolute">
        <axis xyz="0 1 0"/>
        <limit effort="0" lower="-0.227" upper="1.618" velocity="0"/>
        <parent link="link_2.0"/>
        <child link="link_3.0"/>
        <origin xyz="0 0 0.0384"/>
    </joint>

    <!--<link name="link_3.0_tip">
        <inertial>
            <mass value="0.0096" />
            <origin xyz="0 0 0" rpy="0 0 0"/>
            <inertia ixx="4.701248e-06" ixy="1.255968e-06" ixz="1.2936e-06"
                       iyy="3.649312e-06" iyz="1.7622e-06"
                       izz="4.701248e-06" />
        </inertial>
        <visual>
            <origin xyz="0.0 0.0 0.0" rpy="0 0 0" />
            <geometry>
                <mesh filename="link_3.0_tip.obj"/>
            </geometry>
            <material name="black"/>
        </visual>
        <collision>
        </collision>
    </link>

    <joint name="joint_3.0_tip" type="fixed">
        <parent link="link_3.0"/>
        <child link="link_3.0_tip"/>
        <origin rpy="0 0 0" xyz="0 0 0.0267"/>
    </joint> -->

    <link name="link_4.0">
        <inertial>
            <mass value="0.0119" />
            <origin xyz="0 0 0" rpy="0 0 0"/>
            <inertia ixx="1.01666658333e-06" ixy="0.0" ixz="0.0" iyy="6.47677333333e-07" iyz="0.0" izz=" 1.01666658333e-06" />
        </inertial>
        <visual>
            <geometry>
                <mesh filename="link_0.0.obj"/>
            </geometry>
            <material name="black"/>
        </visual>
        <collision>
        </collision>
    </link> 

    <joint name="joint_4.0" type="revolute">
        <axis xyz="0 0 1"/>
        <limit effort="0" lower="-0.47" upper="0.47" velocity="0"/>
        <parent link="base_link"/>
        <child link="link_4.0"/>
        <origin xyz="0.0 0.0 0.0007" rpy="0.0 0.0 0.0"/>
    </joint>

    <link name="link_5.0">
        <inertial>
            <mass value="0.065" />
            <origin xyz="0 0 0" rpy="0 0 0"/>
            <inertia ixx="7.95654166667e-05" ixy="1.7199e-05" ixz="8.75875e-06" iyy="2.47088833333e-05" iyz="2.413125e-05" izz="7.95654166667e-05" />
        </inertial>
        <visual>
            <geometry>
                <mesh filename="link_1.0.obj"/>
            </geometry>
            <material name="black"/>
        </visual>
        <collision>
            <origin xyz="0 0 0.0" rpy="0 0 0" />
            <geometry>
                <mesh filename="link_1.0.obj" scale="1 1 1" />
            </geometry> 
        </collision>
    </link>
    
    <joint name="joint_5.0" type="revolute">
        <limit effort="0" lower="-0.196" upper="1.61" velocity="0"/>
        <axis xyz="0 1 0"/>
        <parent link="link_4.0"/>
        <child link="link_5.0"/>
        <origin xyz="0 0 0.0164"/>
    </joint>
    
    <link name="link_6.0">
        <inertial>
            <mass value="0.0355" />
            <origin xyz="0 0 0" rpy="0 0 0"/>
            <inertia ixx="2.63979183333e-05" ixy="6.67968e-06" ixz="4.783625e-06"
                       iyy="1.34948516667e-05" iyz="9.372e-06"
                       izz="2.63979183333e-05" />
        </inertial>
    <visual>
        <geometry>
            <mesh filename="link_2.0.obj"/>
        </geometry>
        <material name="black"/>
    </visual>
    <collision>
        <origin xyz="0 0 0.0" rpy="0 0 0" />
            <geometry>
                <mesh filename="link_2.0.obj" scale="1 1 1" />
            </geometry> 
    </collision>
    </link>
    
    <joint name="joint_6.0" type="revolute">
        <axis xyz="0 1 0"/>
        <limit effort="0" lower="-0.174" upper="1.709" velocity="0"/>
        <parent link="link_5.0"/>
        <child link="link_6.0"/>
        <origin xyz="0 0 0.054"/>
    </joint>
    
    <link name="link_7.0">
        <!--<inertial>
            <mass value="0.0096" />
            <origin xyz="0 0 0" rpy="0 0 0"/>
            <inertia ixx="4.701248e-06" ixy="1.255968e-06" ixz="1.2936e-06"
                       iyy="3.649312e-06" iyz="1.7622e-06"
                       izz="4.701248e-06" />
        </inertial>-->
        <inertial>
            <mass value="0.1128" />
            <origin xyz="0 0 0.00397659574" rpy="0 0 0"/>
            <inertia ixx="4.701248e-06" ixy="1.255968e-06" ixz="1.2936e-06"
                       iyy="3.649312e-06" iyz="1.7622e-06"
                       izz="4.701248e-06" /> <!-- TODO: change the inertia, are you sure you can apply the parallel theorem? the inertia tensor is probably not associated to the center of mass. -->
        </inertial>
        <visual>
            <geometry>
                <mesh filename="link_3.0.obj"/>
            </geometry>
            <material name="black"/>
        </visual>
        <visual>
            <origin xyz="0.0 0.0 0.0267" rpy="0 0 0" />
            <geometry>
                <mesh filename="link_3.0_tip.obj"/>
            </geometry>
            <material name="black"/>
        </visual>
        <!--<collision>
            <origin xyz="0 0 0" rpy="0 0 0" />
            <geometry>
                <mesh filename="link_3.0.obj" scale="1 1 1" />
            </geometry>            
        </collision>-->
        <collision>
            <origin xyz="0 0 0.0267" rpy="0 0 0" />
            <geometry>
                <!--<mesh filename="link_3.0_tip.obj" scale="1 1 1" />-->
                <sphere radius="0.012"/>
            </geometry>            
        </collision>
    </link>
    
    <joint name="joint_7.0" type="revolute">
        <axis xyz="0 1 0"/>
        <limit effort="0" lower="-0.227" upper="1.618" velocity="0"/>
        <parent link="link_6.0"/>
        <child link="link_7.0"/>
        <origin xyz="0 0 0.0384"/>
    </joint>

    <link name="link_8.0">
        <inertial>
            <mass value="0.0119" />
            <origin xyz="0 0 0" rpy="0 0 0"/>
            <inertia ixx="1.01666658333e-06" ixy="0.0" ixz="0.0" iyy="6.47677333333e-07" iyz="0.0" izz=" 1.01666658333e-06" />
        </inertial>
        <visual>
            <geometry>
                <mesh filename="link_0.0.obj"/>
            </geometry>
            <material name="black"/>
        </visual>
        <collision>
            <origin xyz="0 0 0.0" rpy="0 0 0" />
            <geometry>
                <mesh filename="link_0.0.obj" scale="1 1 1" />
            </geometry> 
        </collision>
    </link>
    
    <joint name="joint_8.0" type="revolute">
        <axis xyz="0 0 1"/>
        <limit effort="0" lower="-0.47" upper="0.47" velocity="0"/>
        <parent link="base_link"/>
        <child link="link_8.0"/>
        <origin rpy="0.08726646255 0 0" xyz="0 -0.0435 -0.001542"/>
    </joint>
    
    <link name="link_9.0">
        <inertial>
            <mass value="0.065" />
            <origin xyz="0 0 0" rpy="0 0 0"/>
            <inertia ixx="7.95654166667e-05" ixy="1.7199e-05" ixz="8.75875e-06" iyy="2.47088833333e-05" iyz="2.413125e-05" izz="7.95654166667e-05" />
        </inertial>
        <visual>
            <geometry>
                <mesh filename="link_1.0.obj"/>
            </geometry>
            <material name="black"/>
        </visual>
        <collision>
            <origin xyz="0 0 0.0" rpy="0 0 0" />
            <geometry>
                <mesh filename="link_1.0.obj" scale="1 1 1" />
            </geometry> 
        </collision>
    </link>
    
    <joint name="joint_9.0" type="revolute">
        <limit effort="0" lower="-0.196" upper="1.61" velocity="0"/>
        <axis xyz="0 1 0"/>
        <parent link="link_8.0"/>
        <child link="link_9.0"/>
        <origin xyz="0 0 0.0164"/>
    </joint>
    
    <link name="link_10.0">
        <inertial>
            <mass value="0.0355" />
            <origin xyz="0 0 0" rpy="0 0 0"/>
            <inertia ixx="2.63979183333e-05" ixy="6.67968e-06" ixz="4.783625e-06"
                       iyy="1.34948516667e-05" iyz="9.372e-06"
                       izz="2.63979183333e-05" />
        </inertial>
        <visual>
            <geometry>
                <mesh filename="link_2.0.obj"/>
            </geometry>
            <material name="black"/>
        </visual>
        <collision>
            <origin xyz="0 0 0.0" rpy="0 0 0" />
            <geometry>
                <mesh filename="link_2.0.obj" scale="1 1 1" />
            </geometry> 
        </collision>
    </link>
    
    <joint name="joint_10.0" type="revolute">
        <axis xyz="0 1 0"/>
        <limit effort="0" lower="-0.174" upper="1.709" velocity="0"/>
        <parent link="link_9.0"/>
        <child link="link_10.0"/>
        <origin xyz="0 0 0.054"/>
    </joint>
    
    <link name="link_11.0">
        <!--<inertial>
            <mass value="0.0096" />
            <origin xyz="0 0 0" rpy="0 0 0"/>
            <inertia ixx="4.701248e-06" ixy="1.255968e-06" ixz="1.2936e-06"
                       iyy="3.649312e-06" iyz="1.7622e-06"
                       izz="4.701248e-06" />
        </inertial>-->
        <inertial>
            <mass value="0.1128" />
            <origin xyz="0 0 0.00397659574" rpy="0 0 0"/>
            <inertia ixx="4.701248e-06" ixy="1.255968e-06" ixz="1.2936e-06"
                       iyy="3.649312e-06" iyz="1.7622e-06"
                       izz="4.701248e-06" /> <!-- TODO: change the inertia, are you sure you can apply the parallel theorem? the inertia tensor is probably not associated to the center of mass. -->
        </inertial>
        <visual>
            <geometry>
                <mesh filename="link_3.0.obj"/>
            </geometry>
            <material name="black"/>
        </visual>
        <visual>
            <origin xyz="0.0 0.0 0.0267" rpy="0 0 0" />
            <geometry>
                <mesh filename="link_3.0_tip.obj"/>
            </geometry>
            <material name="black"/>
        </visual>
        <!--<collision>
            <origin xyz="0 0 0" rpy="0 0 0" />
            <geometry>
                <mesh filename="link_3.0.obj" scale="1 1 1" />
            </geometry>            
        </collision> -->
        <collision>
            <origin xyz="0.0 0.0 0.0267" rpy="0 0 0" />
            <geometry>
                <!--<mesh filename="link_3.0_tip.obj" scale="1 1 1" />-->
                <sphere radius="0.012"/>
            </geometry>            
        </collision>
    </link>
    
    <joint name="joint_11.0" type="revolute">
        <axis xyz="0 1 0"/>
        <limit effort="0" lower="-0.227" upper="1.618" velocity="0"/>
        <parent link="link_10.0"/>
        <child link="link_11.0"/>
        <origin xyz="0 0 0.0384"/>
    </joint>
    
     <!-- THUMB -->
    <link name="link_12.0">
        <inertial>
            <origin xyz="0.0 0.0 0.0" rpy="0 0 0" />
            <mass value="0.0176" />
            <inertia ixx="1.89273333333e-5" iyy="1.43008213333e-05" izz="1.89273333333e-05" ixy="7.16716e-06" ixz="5.35568e-06" iyz="6.8068e-06" />
        </inertial>
        <visual>
            <geometry>
                <mesh filename="link_12.0_right.obj"/>
            </geometry>
            <material name="black">
            <color rgba=".2 .2 .2 1"/>
            </material>
        </visual>
        <collision>
            <!--<origin xyz="0 0 0.0" rpy="0 0 0" />
            <geometry>
                <mesh filename="link_12.0_right.obj" scale="1 1 1" />
            </geometry> -->
        </collision> 
    </link>
    
    <joint name="joint_912.0" type="revolute">
        <axis xyz="1 0 0"/>
        <limit effort="0" lower="0.263" upper="1.396" velocity="0"/>
        <parent link="base_link"/>
        <child link="link_12.0"/>
        <origin rpy="0 -1.65806278845 -1.5707963259" xyz="-0.0182 0.019333 -0.045987"/>
    </joint>
    
    <link name="link_13.0">
        <inertial>
            <origin xyz="0.0 0.0 0.0" rpy="0 0 0" />
            <mass value="0.0119" />
            <inertia ixx="4.24250866667e-06" iyy="4.52362633333e-06" izz="4.24250866667e-06" ixy="1.032087e-06" ixz="1.603525e-06" iyz="1.44808125e-06" />
        </inertial>
        <visual>
            <geometry>
                <mesh filename="link_13.0.obj"/>
            </geometry>
            <material name="black">
                <color rgba=".2 .2 .2 1"/>
            </material>
            </visual>
        <collision>
            <!--<origin xyz="0 0 0.0" rpy="0 0 0" />
            <geometry>
                <mesh filename="link_13.0.obj" scale="1 1 1" />
            </geometry> -->
        </collision>
    </link>
    
    <joint name="joint_913.0" type="revolute">
        <axis xyz="0 0 1"/>
        <limit effort="0" lower="-0.105" upper="1.163" velocity="0"/>
        <parent link="link_12.0"/>
        <child link="link_13.0"/>
        <!-- RIGHT -->
        <origin xyz="-0.027 0.005 0.0399"/>
        <!-- LEFT -->
        <!-- <origin xyz="-0.027 -0.005 0.0399"/> -->
    </joint>
    
    <link name="link_14.0">
        <inertial>
            <origin xyz="0.0 0.0 0.0" rpy="0 0 0" />
            <mass value="0.038" />
            <inertia ixx="4.30439933333e-05" iyy="1.44451933333e-05" izz="4.30439933333e-05" ixy="9.57068e-06" ixz="5.1205e-06" iyz="1.342825e-05" />
        </inertial>
        <visual>
            <geometry>
                <mesh filename="link_14.0.obj"/>
            </geometry>
            <material name="black">
            </material>
        </visual>
        <collision>
            <!--<origin xyz="0 0 0.0" rpy="0 0 0" />
            <geometry>
                <mesh filename="link_14.0.obj" scale="1 1 1" />
            </geometry> -->
        </collision>
    </link>
    
    <joint name="joint_914.0" type="revolute">
        <axis xyz="0 1 0"/>
        <limit effort="0" lower="-0.189" upper="1.644" velocity="0"/>
        <parent link="link_13.0"/>
        <child link="link_14.0"/>
        <origin xyz="0 0 0.0177"/>
    </joint>
    
    <link name="link_15.0">
        <inertial>
            <origin xyz="0.0 0.0 0.0" rpy="0 0 0" />
            <mass value="0.0388" />
            <inertia ixx="3.29223173333e-05" iyy="1.47493026667e-5" izz="3.29223173333e-05" ixy="8.042076e-06" ixz="5.2283e-06" iyz="1.1283525e-5" />
        </inertial>
        <visual>
            <geometry>
                <mesh filename="link_15.0.obj"/>
            </geometry>
            <material name="black">
            </material>
        </visual>
        <visual>
            <origin xyz="0.0 0.0 0.0423" rpy="0 0 0" />
            <geometry>
                <mesh filename="link_3.0_tip.obj"/>
            </geometry>
            <material name="black"/>
        </visual>
        <collision>
            <origin xyz="0 0 0.0423" rpy="0 0 0" />
            <geometry>
                <!--<mesh filename="link_15.0.obj" scale="1 1 1" />-->
                <sphere radius="0.012"/>
            </geometry> 
        </collision>
    </link>

    <joint name="joint_915.0" type="revolute">
        <axis xyz="0 1 0"/>
        <limit effort="0" lower="-0.162" upper="1.719" velocity="0"/>
        <parent link="link_14.0"/>
        <child link="link_15.0"/>
        <origin xyz="0 0 0.0514"/>
    </joint>
</robot>
